go/tests/test_20240310150240.in
10
0-9 o
0 B 1 MSFT 2705 30
0 S 2 META 3260 1
0 C 1
0 S 3 MSFT 2701 25
0 B 4 AAPL 3290 10
0 C 2
1 B 5 AMD 2705 30
1 S 6 AAPL 3260 1
1 C 5
1 S 7 AMD 2701 25
1 B 8 AMZN 3290 10
1 C 6
2 B 9 NVDA 2705 30
2 S 10 GOOGL 3260 1
2 C 9
2 S 11 META 2701 25
2 B 12 AMZN 3290 10
2 C 10
3 B 13 AMD 2705 30
3 S 14 AMD 3260 1
3 C 13
3 S 15 INTC 2701 25
3 B 16 INTC 3290 10
3 C 14
4 B 17 TSLA 2705 30
4 S 18 AMD 3260 1
4 C 17
4 S 19 AMZN 2701 25
4 B 20 META 3290 10
4 C 18
5 B 21 META 2705 30
5 S 22 AMD 3260 1
5 C 21
5 S 23 INTC 2701 25
5 B 24 TSLA 3290 10
5 C 22
6 B 25 INTC 2705 30
6 S 26 GOOGL 3260 1
6 C 25
6 S 27 AMZN 2701 25
6 B 28 MSFT 3290 10
6 C 26
7 B 29 NVDA 2705 30
7 S 30 NFLX 3260 1
7 C 29
7 S 31 MSFT 2701 25
7 B 32 AMD 3290 10
7 C 30
8 B 33 AMD 2705 30
8 S 34 GOOGL 3260 1
8 C 33
8 S 35 GOOGL 2701 25
8 B 36 MSFT 3290 10
8 C 34
9 B 37 META 2705 30
9 S 38 TSLA 3260 1
9 C 37
9 S 39 AMD 2701 25
9 B 40 NFLX 3290 10
9 C 38
.
0-9 x
